{
 "cells": [
  {
   "cell_type": "markdown",
   "id": "2f453fd5",
   "metadata": {},
   "source": [
    "# Get location of new photos on the computer"
   ]
  },
  {
   "cell_type": "code",
   "execution_count": 1,
   "id": "e4aefcba",
   "metadata": {},
   "outputs": [
    {
     "name": "stdout",
     "output_type": "stream",
     "text": [
      "List of selected photoes:\n",
      "/Users/tiginamaria1999/PycharmProjects/itmo_ct/resources/images_to_process/IMG_20191231_201832.jpg\n",
      "/Users/tiginamaria1999/PycharmProjects/itmo_ct/resources/images_to_process/IMG_20191226_213412.jpg\n",
      "/Users/tiginamaria1999/PycharmProjects/itmo_ct/resources/images_to_process/IMG_20191201_134356.jpg\n",
      "/Users/tiginamaria1999/PycharmProjects/itmo_ct/resources/images_to_process/IMG_20181206_160945.jpg\n",
      "/Users/tiginamaria1999/PycharmProjects/itmo_ct/resources/images_to_process/IMG_20180926_142258.jpg\n",
      "/Users/tiginamaria1999/PycharmProjects/itmo_ct/resources/images_to_process/IMG_20180915_104645.jpg\n",
      "/Users/tiginamaria1999/PycharmProjects/itmo_ct/resources/images_to_process/IMG_20180426_125203.jpg\n",
      "/Users/tiginamaria1999/PycharmProjects/itmo_ct/resources/images_to_process/IMG_20180425_163903.jpg\n",
      "/Users/tiginamaria1999/PycharmProjects/itmo_ct/resources/images_to_process/IMG_20180425_161719.jpg\n",
      "/Users/tiginamaria1999/PycharmProjects/itmo_ct/resources/images_to_process/IMG_20180425_161709.jpg\n",
      "/Users/tiginamaria1999/PycharmProjects/itmo_ct/resources/images_to_process/IMG_20180425_142208.jpg\n",
      "/Users/tiginamaria1999/PycharmProjects/itmo_ct/resources/images_to_process/IMG_20180406_130443.jpg\n",
      "/Users/tiginamaria1999/PycharmProjects/itmo_ct/resources/images_to_process/IMG_20180405_091312.jpg\n",
      "/Users/tiginamaria1999/PycharmProjects/itmo_ct/resources/images_to_process/IMG_20180321_182350.jpg\n",
      "/Users/tiginamaria1999/PycharmProjects/itmo_ct/resources/images_to_process/IMG_20180320_122446.jpg\n",
      "/Users/tiginamaria1999/PycharmProjects/itmo_ct/resources/images_to_process/IMG_20180320_115130.jpg\n",
      "/Users/tiginamaria1999/PycharmProjects/itmo_ct/resources/images_to_process/IMG_20180314_135858.jpg\n",
      "/Users/tiginamaria1999/PycharmProjects/itmo_ct/resources/images_to_process/IMG_20180222_132521.jpg\n",
      "/Users/tiginamaria1999/PycharmProjects/itmo_ct/resources/images_to_process/IMG_6774.JPG\n",
      "/Users/tiginamaria1999/PycharmProjects/itmo_ct/resources/images_to_process/IMG_6615.JPG\n",
      "/Users/tiginamaria1999/PycharmProjects/itmo_ct/resources/images_to_process/IMG_6595.JPG\n",
      "/Users/tiginamaria1999/PycharmProjects/itmo_ct/resources/images_to_process/IMG_4478.JPG\n",
      "/Users/tiginamaria1999/PycharmProjects/itmo_ct/resources/images_to_process/IMG_4380.JPG\n",
      "/Users/tiginamaria1999/PycharmProjects/itmo_ct/resources/images_to_process/IMG_4378.JPG\n",
      "/Users/tiginamaria1999/PycharmProjects/itmo_ct/resources/images_to_process/IMG_2569.JPG\n"
     ]
    }
   ],
   "source": [
    "# Importing required modules\n",
    "import sys\n",
    "from ui.gui_requests_handler import select_photos_to_upload\n",
    "\n",
    "selected_photos = select_photos_to_upload()\n",
    "print(f\"List of selected photoes:\")\n",
    "print(*selected_photos, sep='\\n')"
   ]
  },
  {
   "cell_type": "markdown",
   "id": "c223e790",
   "metadata": {},
   "source": [
    "# Add new entries to Photos table of database, check if exists"
   ]
  },
  {
   "cell_type": "code",
   "execution_count": 2,
   "id": "0efbf684",
   "metadata": {},
   "outputs": [
    {
     "name": "stderr",
     "output_type": "stream",
     "text": [
      "WARNING:root:Given datetime 2019-12-31 20:18:33 is more then 1 year back\n"
     ]
    },
    {
     "name": "stdout",
     "output_type": "stream",
     "text": [
      "25/25 have been successfully uploaded\n"
     ]
    },
    {
     "name": "stderr",
     "output_type": "stream",
     "text": [
      "WARNING:root:DateTime and GPSInfo not provided in image exif data.\n"
     ]
    },
    {
     "name": "stdout",
     "output_type": "stream",
     "text": [
      "Service can not detect where IMG_20191226_213412.jpg was made?\n",
      "Please, enter address (e.x. Ленинский пр. 161, 13) or location (e.x. 30.23 60.132) for it:\n",
      "Невский проспект\n",
      "Got address: Невский проспект, detect location (59.932473, 30.349169)\n",
      "Please, enter datetime (e.x. 2021-10-25 09:31:32) for it:\n",
      "\n"
     ]
    },
    {
     "name": "stderr",
     "output_type": "stream",
     "text": [
      "ERROR:root:Can not get datetime from string \n",
      "--- Logging error ---\n",
      "Traceback (most recent call last):\n",
      "  File \"/Users/tiginamaria1999/PycharmProjects/itmo_ct/database/database_client_sqlite.py\", line 145, in _add_images_info_to_database\n",
      "    self._add_exif_info_for_image(image_id)\n",
      "  File \"/Users/tiginamaria1999/PycharmProjects/itmo_ct/database/database_client_sqlite.py\", line 101, in _add_exif_info_for_image\n",
      "    raise Exception(f\"Failed to get or read exif info for image: {image_id}\")\n",
      "Exception: Failed to get or read exif info for image: 24\n",
      "\n",
      "During handling of the above exception, another exception occurred:\n",
      "\n",
      "Traceback (most recent call last):\n",
      "  File \"/usr/local/Cellar/python@3.9/3.9.6/Frameworks/Python.framework/Versions/3.9/lib/python3.9/logging/__init__.py\", line 1083, in emit\n",
      "    msg = self.format(record)\n",
      "  File \"/usr/local/Cellar/python@3.9/3.9.6/Frameworks/Python.framework/Versions/3.9/lib/python3.9/logging/__init__.py\", line 927, in format\n",
      "    return fmt.format(record)\n",
      "  File \"/usr/local/Cellar/python@3.9/3.9.6/Frameworks/Python.framework/Versions/3.9/lib/python3.9/logging/__init__.py\", line 663, in format\n",
      "    record.message = record.getMessage()\n",
      "  File \"/usr/local/Cellar/python@3.9/3.9.6/Frameworks/Python.framework/Versions/3.9/lib/python3.9/logging/__init__.py\", line 367, in getMessage\n",
      "    msg = msg % self.args\n",
      "TypeError: not all arguments converted during string formatting\n",
      "Call stack:\n",
      "  File \"/usr/local/Cellar/python@3.9/3.9.6/Frameworks/Python.framework/Versions/3.9/lib/python3.9/runpy.py\", line 197, in _run_module_as_main\n",
      "    return _run_code(code, main_globals, None,\n",
      "  File \"/usr/local/Cellar/python@3.9/3.9.6/Frameworks/Python.framework/Versions/3.9/lib/python3.9/runpy.py\", line 87, in _run_code\n",
      "    exec(code, run_globals)\n",
      "  File \"/usr/local/lib/python3.9/site-packages/ipykernel_launcher.py\", line 16, in <module>\n",
      "    app.launch_new_instance()\n",
      "  File \"/usr/local/lib/python3.9/site-packages/traitlets/config/application.py\", line 846, in launch_instance\n",
      "    app.start()\n",
      "  File \"/usr/local/lib/python3.9/site-packages/ipykernel/kernelapp.py\", line 677, in start\n",
      "    self.io_loop.start()\n",
      "  File \"/usr/local/lib/python3.9/site-packages/tornado/platform/asyncio.py\", line 199, in start\n",
      "    self.asyncio_loop.run_forever()\n",
      "  File \"/usr/local/Cellar/python@3.9/3.9.6/Frameworks/Python.framework/Versions/3.9/lib/python3.9/asyncio/base_events.py\", line 596, in run_forever\n",
      "    self._run_once()\n",
      "  File \"/usr/local/Cellar/python@3.9/3.9.6/Frameworks/Python.framework/Versions/3.9/lib/python3.9/asyncio/base_events.py\", line 1890, in _run_once\n",
      "    handle._run()\n",
      "  File \"/usr/local/Cellar/python@3.9/3.9.6/Frameworks/Python.framework/Versions/3.9/lib/python3.9/asyncio/events.py\", line 80, in _run\n",
      "    self._context.run(self._callback, *self._args)\n",
      "  File \"/usr/local/lib/python3.9/site-packages/ipykernel/kernelbase.py\", line 457, in dispatch_queue\n",
      "    await self.process_one()\n",
      "  File \"/usr/local/lib/python3.9/site-packages/ipykernel/kernelbase.py\", line 446, in process_one\n",
      "    await dispatch(*args)\n",
      "  File \"/usr/local/lib/python3.9/site-packages/ipykernel/kernelbase.py\", line 353, in dispatch_shell\n",
      "    await result\n",
      "  File \"/usr/local/lib/python3.9/site-packages/ipykernel/kernelbase.py\", line 648, in execute_request\n",
      "    reply_content = await reply_content\n",
      "  File \"/usr/local/lib/python3.9/site-packages/ipykernel/ipkernel.py\", line 353, in do_execute\n",
      "    res = shell.run_cell(code, store_history=store_history, silent=silent)\n",
      "  File \"/usr/local/lib/python3.9/site-packages/ipykernel/zmqshell.py\", line 533, in run_cell\n",
      "    return super(ZMQInteractiveShell, self).run_cell(*args, **kwargs)\n",
      "  File \"/usr/local/lib/python3.9/site-packages/IPython/core/interactiveshell.py\", line 2901, in run_cell\n",
      "    result = self._run_cell(\n",
      "  File \"/usr/local/lib/python3.9/site-packages/IPython/core/interactiveshell.py\", line 2947, in _run_cell\n",
      "    return runner(coro)\n",
      "  File \"/usr/local/lib/python3.9/site-packages/IPython/core/async_helpers.py\", line 68, in _pseudo_sync_runner\n",
      "    coro.send(None)\n",
      "  File \"/usr/local/lib/python3.9/site-packages/IPython/core/interactiveshell.py\", line 3172, in run_cell_async\n",
      "    has_raised = await self.run_ast_nodes(code_ast.body, cell_name,\n",
      "  File \"/usr/local/lib/python3.9/site-packages/IPython/core/interactiveshell.py\", line 3364, in run_ast_nodes\n",
      "    if (await self.run_code(code, result,  async_=asy)):\n",
      "  File \"/usr/local/lib/python3.9/site-packages/IPython/core/interactiveshell.py\", line 3444, in run_code\n",
      "    exec(code_obj, self.user_global_ns, self.user_ns)\n",
      "  File \"/var/folders/4s/hl9y6lqs3h1c9qxxnbjmtvsr0000gn/T/ipykernel_32875/718171376.py\", line 8, in <module>\n",
      "    db_client.add_images(selected_photos)\n",
      "  File \"/Users/tiginamaria1999/PycharmProjects/itmo_ct/database/database_client_sqlite.py\", line 166, in add_images\n",
      "    processed_image_ids = self._add_images_info_to_database(added_image_ids)\n",
      "  File \"/Users/tiginamaria1999/PycharmProjects/itmo_ct/database/database_client_sqlite.py\", line 150, in _add_images_info_to_database\n",
      "    logging.error(f'Skipping image {image_id} due to error:', e)\n",
      "Message: 'Skipping image 24 due to error:'\n",
      "Arguments: (Exception('Failed to get or read exif info for image: 24'),)\n",
      "WARNING:root:DateTime and GPSInfo not provided in image exif data.\n"
     ]
    },
    {
     "name": "stdout",
     "output_type": "stream",
     "text": [
      "Service can not detect where IMG_20191201_134356.jpg was made?\n",
      "Please, enter address (e.x. Ленинский пр. 161, 13) or location (e.x. 30.23 60.132) for it:\n",
      "\n",
      "Got address: , detect location (68.015588, 168.948015)\n",
      "Please, enter datetime (e.x. 2021-10-25 09:31:32) for it:\n",
      "\n"
     ]
    },
    {
     "name": "stderr",
     "output_type": "stream",
     "text": [
      "ERROR:root:Can not get datetime from string \n",
      "--- Logging error ---\n",
      "Traceback (most recent call last):\n",
      "  File \"/Users/tiginamaria1999/PycharmProjects/itmo_ct/database/database_client_sqlite.py\", line 145, in _add_images_info_to_database\n",
      "    self._add_exif_info_for_image(image_id)\n",
      "  File \"/Users/tiginamaria1999/PycharmProjects/itmo_ct/database/database_client_sqlite.py\", line 101, in _add_exif_info_for_image\n",
      "    raise Exception(f\"Failed to get or read exif info for image: {image_id}\")\n",
      "Exception: Failed to get or read exif info for image: 25\n",
      "\n",
      "During handling of the above exception, another exception occurred:\n",
      "\n",
      "Traceback (most recent call last):\n",
      "  File \"/usr/local/Cellar/python@3.9/3.9.6/Frameworks/Python.framework/Versions/3.9/lib/python3.9/logging/__init__.py\", line 1083, in emit\n",
      "    msg = self.format(record)\n",
      "  File \"/usr/local/Cellar/python@3.9/3.9.6/Frameworks/Python.framework/Versions/3.9/lib/python3.9/logging/__init__.py\", line 927, in format\n",
      "    return fmt.format(record)\n",
      "  File \"/usr/local/Cellar/python@3.9/3.9.6/Frameworks/Python.framework/Versions/3.9/lib/python3.9/logging/__init__.py\", line 663, in format\n",
      "    record.message = record.getMessage()\n",
      "  File \"/usr/local/Cellar/python@3.9/3.9.6/Frameworks/Python.framework/Versions/3.9/lib/python3.9/logging/__init__.py\", line 367, in getMessage\n",
      "    msg = msg % self.args\n",
      "TypeError: not all arguments converted during string formatting\n",
      "Call stack:\n",
      "  File \"/usr/local/Cellar/python@3.9/3.9.6/Frameworks/Python.framework/Versions/3.9/lib/python3.9/runpy.py\", line 197, in _run_module_as_main\n",
      "    return _run_code(code, main_globals, None,\n",
      "  File \"/usr/local/Cellar/python@3.9/3.9.6/Frameworks/Python.framework/Versions/3.9/lib/python3.9/runpy.py\", line 87, in _run_code\n",
      "    exec(code, run_globals)\n",
      "  File \"/usr/local/lib/python3.9/site-packages/ipykernel_launcher.py\", line 16, in <module>\n",
      "    app.launch_new_instance()\n",
      "  File \"/usr/local/lib/python3.9/site-packages/traitlets/config/application.py\", line 846, in launch_instance\n",
      "    app.start()\n",
      "  File \"/usr/local/lib/python3.9/site-packages/ipykernel/kernelapp.py\", line 677, in start\n",
      "    self.io_loop.start()\n",
      "  File \"/usr/local/lib/python3.9/site-packages/tornado/platform/asyncio.py\", line 199, in start\n",
      "    self.asyncio_loop.run_forever()\n",
      "  File \"/usr/local/Cellar/python@3.9/3.9.6/Frameworks/Python.framework/Versions/3.9/lib/python3.9/asyncio/base_events.py\", line 596, in run_forever\n",
      "    self._run_once()\n",
      "  File \"/usr/local/Cellar/python@3.9/3.9.6/Frameworks/Python.framework/Versions/3.9/lib/python3.9/asyncio/base_events.py\", line 1890, in _run_once\n",
      "    handle._run()\n",
      "  File \"/usr/local/Cellar/python@3.9/3.9.6/Frameworks/Python.framework/Versions/3.9/lib/python3.9/asyncio/events.py\", line 80, in _run\n",
      "    self._context.run(self._callback, *self._args)\n",
      "  File \"/usr/local/lib/python3.9/site-packages/ipykernel/kernelbase.py\", line 457, in dispatch_queue\n",
      "    await self.process_one()\n",
      "  File \"/usr/local/lib/python3.9/site-packages/ipykernel/kernelbase.py\", line 446, in process_one\n",
      "    await dispatch(*args)\n",
      "  File \"/usr/local/lib/python3.9/site-packages/ipykernel/kernelbase.py\", line 353, in dispatch_shell\n",
      "    await result\n",
      "  File \"/usr/local/lib/python3.9/site-packages/ipykernel/kernelbase.py\", line 648, in execute_request\n",
      "    reply_content = await reply_content\n",
      "  File \"/usr/local/lib/python3.9/site-packages/ipykernel/ipkernel.py\", line 353, in do_execute\n",
      "    res = shell.run_cell(code, store_history=store_history, silent=silent)\n",
      "  File \"/usr/local/lib/python3.9/site-packages/ipykernel/zmqshell.py\", line 533, in run_cell\n",
      "    return super(ZMQInteractiveShell, self).run_cell(*args, **kwargs)\n",
      "  File \"/usr/local/lib/python3.9/site-packages/IPython/core/interactiveshell.py\", line 2901, in run_cell\n",
      "    result = self._run_cell(\n",
      "  File \"/usr/local/lib/python3.9/site-packages/IPython/core/interactiveshell.py\", line 2947, in _run_cell\n",
      "    return runner(coro)\n",
      "  File \"/usr/local/lib/python3.9/site-packages/IPython/core/async_helpers.py\", line 68, in _pseudo_sync_runner\n",
      "    coro.send(None)\n",
      "  File \"/usr/local/lib/python3.9/site-packages/IPython/core/interactiveshell.py\", line 3172, in run_cell_async\n",
      "    has_raised = await self.run_ast_nodes(code_ast.body, cell_name,\n",
      "  File \"/usr/local/lib/python3.9/site-packages/IPython/core/interactiveshell.py\", line 3364, in run_ast_nodes\n",
      "    if (await self.run_code(code, result,  async_=asy)):\n",
      "  File \"/usr/local/lib/python3.9/site-packages/IPython/core/interactiveshell.py\", line 3444, in run_code\n",
      "    exec(code_obj, self.user_global_ns, self.user_ns)\n",
      "  File \"/var/folders/4s/hl9y6lqs3h1c9qxxnbjmtvsr0000gn/T/ipykernel_32875/718171376.py\", line 8, in <module>\n",
      "    db_client.add_images(selected_photos)\n",
      "  File \"/Users/tiginamaria1999/PycharmProjects/itmo_ct/database/database_client_sqlite.py\", line 166, in add_images\n",
      "    processed_image_ids = self._add_images_info_to_database(added_image_ids)\n",
      "  File \"/Users/tiginamaria1999/PycharmProjects/itmo_ct/database/database_client_sqlite.py\", line 150, in _add_images_info_to_database\n",
      "    logging.error(f'Skipping image {image_id} due to error:', e)\n",
      "Message: 'Skipping image 25 due to error:'\n",
      "Arguments: (Exception('Failed to get or read exif info for image: 25'),)\n",
      "WARNING:root:Given datetime 2018-12-06 16:09:46 is more then 1 year back\n",
      "WARNING:root:Given datetime 2019-12-06 16:09:46 is more then 1 year back\n",
      "--- Logging error ---\n",
      "Traceback (most recent call last):\n",
      "  File \"/Users/tiginamaria1999/PycharmProjects/itmo_ct/database/database_client_sqlite.py\", line 145, in _add_images_info_to_database\n",
      "    self._add_exif_info_for_image(image_id)\n",
      "  File \"/Users/tiginamaria1999/PycharmProjects/itmo_ct/database/database_client_sqlite.py\", line 92, in _add_exif_info_for_image\n",
      "    exif_info = get_exif_info_from_image(image_file)\n",
      "  File \"/Users/tiginamaria1999/PycharmProjects/itmo_ct/image_processing/exif_processing.py\", line 40, in get_exif_info_from_image\n",
      "    return ImageExifInfo.from_exif_data(exif_data_dict)\n",
      "  File \"/Users/tiginamaria1999/PycharmProjects/itmo_ct/model/image_exif_info.py\", line 31, in from_exif_data\n",
      "    gps_info=ImageGPSInfo.from_exif_data(exif_data[ExifDataKey.GPS_INFO]),\n",
      "  File \"/Users/tiginamaria1999/PycharmProjects/itmo_ct/model/image_gps_info.py\", line 20, in from_exif_data\n",
      "    lat=ImageGPSInfo._from_rational64u(gps_data_list[2], gps_data_list[1]),\n",
      "KeyError: 2\n",
      "\n",
      "During handling of the above exception, another exception occurred:\n",
      "\n",
      "Traceback (most recent call last):\n",
      "  File \"/usr/local/Cellar/python@3.9/3.9.6/Frameworks/Python.framework/Versions/3.9/lib/python3.9/logging/__init__.py\", line 1083, in emit\n",
      "    msg = self.format(record)\n",
      "  File \"/usr/local/Cellar/python@3.9/3.9.6/Frameworks/Python.framework/Versions/3.9/lib/python3.9/logging/__init__.py\", line 927, in format\n",
      "    return fmt.format(record)\n",
      "  File \"/usr/local/Cellar/python@3.9/3.9.6/Frameworks/Python.framework/Versions/3.9/lib/python3.9/logging/__init__.py\", line 663, in format\n",
      "    record.message = record.getMessage()\n",
      "  File \"/usr/local/Cellar/python@3.9/3.9.6/Frameworks/Python.framework/Versions/3.9/lib/python3.9/logging/__init__.py\", line 367, in getMessage\n",
      "    msg = msg % self.args\n",
      "TypeError: not all arguments converted during string formatting\n",
      "Call stack:\n",
      "  File \"/usr/local/Cellar/python@3.9/3.9.6/Frameworks/Python.framework/Versions/3.9/lib/python3.9/runpy.py\", line 197, in _run_module_as_main\n",
      "    return _run_code(code, main_globals, None,\n",
      "  File \"/usr/local/Cellar/python@3.9/3.9.6/Frameworks/Python.framework/Versions/3.9/lib/python3.9/runpy.py\", line 87, in _run_code\n",
      "    exec(code, run_globals)\n",
      "  File \"/usr/local/lib/python3.9/site-packages/ipykernel_launcher.py\", line 16, in <module>\n",
      "    app.launch_new_instance()\n",
      "  File \"/usr/local/lib/python3.9/site-packages/traitlets/config/application.py\", line 846, in launch_instance\n",
      "    app.start()\n",
      "  File \"/usr/local/lib/python3.9/site-packages/ipykernel/kernelapp.py\", line 677, in start\n",
      "    self.io_loop.start()\n",
      "  File \"/usr/local/lib/python3.9/site-packages/tornado/platform/asyncio.py\", line 199, in start\n",
      "    self.asyncio_loop.run_forever()\n",
      "  File \"/usr/local/Cellar/python@3.9/3.9.6/Frameworks/Python.framework/Versions/3.9/lib/python3.9/asyncio/base_events.py\", line 596, in run_forever\n",
      "    self._run_once()\n",
      "  File \"/usr/local/Cellar/python@3.9/3.9.6/Frameworks/Python.framework/Versions/3.9/lib/python3.9/asyncio/base_events.py\", line 1890, in _run_once\n",
      "    handle._run()\n",
      "  File \"/usr/local/Cellar/python@3.9/3.9.6/Frameworks/Python.framework/Versions/3.9/lib/python3.9/asyncio/events.py\", line 80, in _run\n",
      "    self._context.run(self._callback, *self._args)\n",
      "  File \"/usr/local/lib/python3.9/site-packages/ipykernel/kernelbase.py\", line 457, in dispatch_queue\n",
      "    await self.process_one()\n",
      "  File \"/usr/local/lib/python3.9/site-packages/ipykernel/kernelbase.py\", line 446, in process_one\n",
      "    await dispatch(*args)\n",
      "  File \"/usr/local/lib/python3.9/site-packages/ipykernel/kernelbase.py\", line 353, in dispatch_shell\n",
      "    await result\n",
      "  File \"/usr/local/lib/python3.9/site-packages/ipykernel/kernelbase.py\", line 648, in execute_request\n",
      "    reply_content = await reply_content\n",
      "  File \"/usr/local/lib/python3.9/site-packages/ipykernel/ipkernel.py\", line 353, in do_execute\n",
      "    res = shell.run_cell(code, store_history=store_history, silent=silent)\n",
      "  File \"/usr/local/lib/python3.9/site-packages/ipykernel/zmqshell.py\", line 533, in run_cell\n",
      "    return super(ZMQInteractiveShell, self).run_cell(*args, **kwargs)\n",
      "  File \"/usr/local/lib/python3.9/site-packages/IPython/core/interactiveshell.py\", line 2901, in run_cell\n",
      "    result = self._run_cell(\n",
      "  File \"/usr/local/lib/python3.9/site-packages/IPython/core/interactiveshell.py\", line 2947, in _run_cell\n",
      "    return runner(coro)\n",
      "  File \"/usr/local/lib/python3.9/site-packages/IPython/core/async_helpers.py\", line 68, in _pseudo_sync_runner\n",
      "    coro.send(None)\n",
      "  File \"/usr/local/lib/python3.9/site-packages/IPython/core/interactiveshell.py\", line 3172, in run_cell_async\n",
      "    has_raised = await self.run_ast_nodes(code_ast.body, cell_name,\n",
      "  File \"/usr/local/lib/python3.9/site-packages/IPython/core/interactiveshell.py\", line 3364, in run_ast_nodes\n",
      "    if (await self.run_code(code, result,  async_=asy)):\n",
      "  File \"/usr/local/lib/python3.9/site-packages/IPython/core/interactiveshell.py\", line 3444, in run_code\n",
      "    exec(code_obj, self.user_global_ns, self.user_ns)\n",
      "  File \"/var/folders/4s/hl9y6lqs3h1c9qxxnbjmtvsr0000gn/T/ipykernel_32875/718171376.py\", line 8, in <module>\n",
      "    db_client.add_images(selected_photos)\n",
      "  File \"/Users/tiginamaria1999/PycharmProjects/itmo_ct/database/database_client_sqlite.py\", line 166, in add_images\n",
      "    processed_image_ids = self._add_images_info_to_database(added_image_ids)\n",
      "  File \"/Users/tiginamaria1999/PycharmProjects/itmo_ct/database/database_client_sqlite.py\", line 150, in _add_images_info_to_database\n",
      "    logging.error(f'Skipping image {image_id} due to error: {e}')\n",
      "Message: 'Skipping image 27 due to error:'\n",
      "Arguments: (KeyError(2),)\n",
      "WARNING:root:Given datetime 2018-09-15 10:46:45 is more then 1 year back\n"
     ]
    },
    {
     "name": "stderr",
     "output_type": "stream",
     "text": [
      "WARNING:root:Given datetime 2019-09-15 10:46:45 is more then 1 year back\n",
      "WARNING:root:Given datetime 2020-09-14 10:46:45 is more then 1 year back\n",
      "WARNING:root:Given datetime 2018-04-26 12:52:04 is more then 1 year back\n",
      "WARNING:root:Given datetime 2019-04-26 12:52:04 is more then 1 year back\n",
      "WARNING:root:Given datetime 2020-04-25 12:52:04 is more then 1 year back\n",
      "WARNING:root:Given datetime 2018-04-25 16:39:04 is more then 1 year back\n",
      "WARNING:root:Given datetime 2019-04-25 16:39:04 is more then 1 year back\n",
      "WARNING:root:Given datetime 2020-04-24 16:39:04 is more then 1 year back\n",
      "WARNING:root:Given datetime 2018-04-25 16:17:19 is more then 1 year back\n",
      "WARNING:root:Given datetime 2019-04-25 16:17:19 is more then 1 year back\n",
      "WARNING:root:Given datetime 2020-04-24 16:17:19 is more then 1 year back\n",
      "WARNING:root:Given datetime 2018-04-25 16:17:09 is more then 1 year back\n",
      "WARNING:root:Given datetime 2019-04-25 16:17:09 is more then 1 year back\n",
      "WARNING:root:Given datetime 2020-04-24 16:17:09 is more then 1 year back\n",
      "WARNING:root:Given datetime 2018-04-25 14:22:08 is more then 1 year back\n",
      "WARNING:root:Given datetime 2019-04-25 14:22:08 is more then 1 year back\n",
      "WARNING:root:Given datetime 2020-04-24 14:22:08 is more then 1 year back\n",
      "WARNING:root:Given datetime 2018-04-06 13:04:43 is more then 1 year back\n",
      "WARNING:root:Given datetime 2019-04-06 13:04:43 is more then 1 year back\n",
      "WARNING:root:Given datetime 2020-04-05 13:04:43 is more then 1 year back\n",
      "WARNING:root:Given datetime 2018-04-05 09:13:13 is more then 1 year back\n",
      "WARNING:root:Given datetime 2019-04-05 09:13:13 is more then 1 year back\n",
      "WARNING:root:Given datetime 2020-04-04 09:13:13 is more then 1 year back\n",
      "WARNING:root:Given datetime 2018-03-21 18:23:50 is more then 1 year back\n",
      "WARNING:root:Given datetime 2019-03-21 18:23:50 is more then 1 year back\n",
      "WARNING:root:Given datetime 2020-03-20 18:23:50 is more then 1 year back\n",
      "WARNING:root:Given datetime 2018-03-20 12:24:46 is more then 1 year back\n",
      "WARNING:root:Given datetime 2019-03-20 12:24:46 is more then 1 year back\n",
      "WARNING:root:Given datetime 2020-03-19 12:24:46 is more then 1 year back\n",
      "WARNING:root:Given datetime 2018-03-20 11:51:30 is more then 1 year back\n",
      "WARNING:root:Given datetime 2019-03-20 11:51:30 is more then 1 year back\n",
      "WARNING:root:Given datetime 2020-03-19 11:51:30 is more then 1 year back\n",
      "WARNING:root:Given datetime 2018-03-14 13:58:58 is more then 1 year back\n",
      "WARNING:root:Given datetime 2019-03-14 13:58:58 is more then 1 year back\n",
      "WARNING:root:Given datetime 2020-03-13 13:58:58 is more then 1 year back\n",
      "WARNING:root:Given datetime 2018-02-22 13:25:22 is more then 1 year back\n",
      "WARNING:root:Given datetime 2019-02-22 13:25:22 is more then 1 year back\n",
      "WARNING:root:Given datetime 2020-02-22 13:25:22 is more then 1 year back\n",
      "WARNING:root:DateTime and GPSInfo not provided in image exif data.\n"
     ]
    },
    {
     "name": "stdout",
     "output_type": "stream",
     "text": [
      "Service can not detect where IMG_4478.JPG was made?\n",
      "Please, enter address (e.x. Ленинский пр. 161, 13) or location (e.x. 30.23 60.132) for it:\n",
      "\n",
      "Got address: , detect location (68.015588, 168.948015)\n",
      "Please, enter datetime (e.x. 2021-10-25 09:31:32) for it:\n",
      "\n"
     ]
    },
    {
     "name": "stderr",
     "output_type": "stream",
     "text": [
      "ERROR:root:Can not get datetime from string \n",
      "--- Logging error ---\n",
      "Traceback (most recent call last):\n",
      "  File \"/Users/tiginamaria1999/PycharmProjects/itmo_ct/database/database_client_sqlite.py\", line 145, in _add_images_info_to_database\n",
      "    self._add_exif_info_for_image(image_id)\n",
      "  File \"/Users/tiginamaria1999/PycharmProjects/itmo_ct/database/database_client_sqlite.py\", line 101, in _add_exif_info_for_image\n",
      "    raise Exception(f\"Failed to get or read exif info for image: {image_id}\")\n",
      "Exception: Failed to get or read exif info for image: 44\n",
      "\n",
      "During handling of the above exception, another exception occurred:\n",
      "\n",
      "Traceback (most recent call last):\n",
      "  File \"/usr/local/Cellar/python@3.9/3.9.6/Frameworks/Python.framework/Versions/3.9/lib/python3.9/logging/__init__.py\", line 1083, in emit\n",
      "    msg = self.format(record)\n",
      "  File \"/usr/local/Cellar/python@3.9/3.9.6/Frameworks/Python.framework/Versions/3.9/lib/python3.9/logging/__init__.py\", line 927, in format\n",
      "    return fmt.format(record)\n",
      "  File \"/usr/local/Cellar/python@3.9/3.9.6/Frameworks/Python.framework/Versions/3.9/lib/python3.9/logging/__init__.py\", line 663, in format\n",
      "    record.message = record.getMessage()\n",
      "  File \"/usr/local/Cellar/python@3.9/3.9.6/Frameworks/Python.framework/Versions/3.9/lib/python3.9/logging/__init__.py\", line 367, in getMessage\n",
      "    msg = msg % self.args\n",
      "TypeError: not all arguments converted during string formatting\n",
      "Call stack:\n",
      "  File \"/usr/local/Cellar/python@3.9/3.9.6/Frameworks/Python.framework/Versions/3.9/lib/python3.9/runpy.py\", line 197, in _run_module_as_main\n",
      "    return _run_code(code, main_globals, None,\n",
      "  File \"/usr/local/Cellar/python@3.9/3.9.6/Frameworks/Python.framework/Versions/3.9/lib/python3.9/runpy.py\", line 87, in _run_code\n",
      "    exec(code, run_globals)\n",
      "  File \"/usr/local/lib/python3.9/site-packages/ipykernel_launcher.py\", line 16, in <module>\n",
      "    app.launch_new_instance()\n",
      "  File \"/usr/local/lib/python3.9/site-packages/traitlets/config/application.py\", line 846, in launch_instance\n",
      "    app.start()\n",
      "  File \"/usr/local/lib/python3.9/site-packages/ipykernel/kernelapp.py\", line 677, in start\n",
      "    self.io_loop.start()\n",
      "  File \"/usr/local/lib/python3.9/site-packages/tornado/platform/asyncio.py\", line 199, in start\n",
      "    self.asyncio_loop.run_forever()\n",
      "  File \"/usr/local/Cellar/python@3.9/3.9.6/Frameworks/Python.framework/Versions/3.9/lib/python3.9/asyncio/base_events.py\", line 596, in run_forever\n",
      "    self._run_once()\n",
      "  File \"/usr/local/Cellar/python@3.9/3.9.6/Frameworks/Python.framework/Versions/3.9/lib/python3.9/asyncio/base_events.py\", line 1890, in _run_once\n",
      "    handle._run()\n",
      "  File \"/usr/local/Cellar/python@3.9/3.9.6/Frameworks/Python.framework/Versions/3.9/lib/python3.9/asyncio/events.py\", line 80, in _run\n",
      "    self._context.run(self._callback, *self._args)\n",
      "  File \"/usr/local/lib/python3.9/site-packages/ipykernel/kernelbase.py\", line 457, in dispatch_queue\n",
      "    await self.process_one()\n",
      "  File \"/usr/local/lib/python3.9/site-packages/ipykernel/kernelbase.py\", line 446, in process_one\n",
      "    await dispatch(*args)\n",
      "  File \"/usr/local/lib/python3.9/site-packages/ipykernel/kernelbase.py\", line 353, in dispatch_shell\n",
      "    await result\n",
      "  File \"/usr/local/lib/python3.9/site-packages/ipykernel/kernelbase.py\", line 648, in execute_request\n",
      "    reply_content = await reply_content\n",
      "  File \"/usr/local/lib/python3.9/site-packages/ipykernel/ipkernel.py\", line 353, in do_execute\n",
      "    res = shell.run_cell(code, store_history=store_history, silent=silent)\n",
      "  File \"/usr/local/lib/python3.9/site-packages/ipykernel/zmqshell.py\", line 533, in run_cell\n",
      "    return super(ZMQInteractiveShell, self).run_cell(*args, **kwargs)\n",
      "  File \"/usr/local/lib/python3.9/site-packages/IPython/core/interactiveshell.py\", line 2901, in run_cell\n",
      "    result = self._run_cell(\n",
      "  File \"/usr/local/lib/python3.9/site-packages/IPython/core/interactiveshell.py\", line 2947, in _run_cell\n",
      "    return runner(coro)\n",
      "  File \"/usr/local/lib/python3.9/site-packages/IPython/core/async_helpers.py\", line 68, in _pseudo_sync_runner\n",
      "    coro.send(None)\n",
      "  File \"/usr/local/lib/python3.9/site-packages/IPython/core/interactiveshell.py\", line 3172, in run_cell_async\n",
      "    has_raised = await self.run_ast_nodes(code_ast.body, cell_name,\n",
      "  File \"/usr/local/lib/python3.9/site-packages/IPython/core/interactiveshell.py\", line 3364, in run_ast_nodes\n",
      "    if (await self.run_code(code, result,  async_=asy)):\n",
      "  File \"/usr/local/lib/python3.9/site-packages/IPython/core/interactiveshell.py\", line 3444, in run_code\n",
      "    exec(code_obj, self.user_global_ns, self.user_ns)\n",
      "  File \"/var/folders/4s/hl9y6lqs3h1c9qxxnbjmtvsr0000gn/T/ipykernel_32875/718171376.py\", line 8, in <module>\n",
      "    db_client.add_images(selected_photos)\n",
      "  File \"/Users/tiginamaria1999/PycharmProjects/itmo_ct/database/database_client_sqlite.py\", line 166, in add_images\n",
      "    processed_image_ids = self._add_images_info_to_database(added_image_ids)\n",
      "  File \"/Users/tiginamaria1999/PycharmProjects/itmo_ct/database/database_client_sqlite.py\", line 150, in _add_images_info_to_database\n",
      "    logging.error(f'Skipping image {image_id} due to error: {e}')\n",
      "Message: 'Skipping image 44 due to error:'\n",
      "Arguments: (Exception('Failed to get or read exif info for image: 44'),)\n",
      "WARNING:root:DateTime and GPSInfo not provided in image exif data.\n"
     ]
    },
    {
     "name": "stdout",
     "output_type": "stream",
     "text": [
      "Service can not detect where IMG_4380.JPG was made?\n",
      "Please, enter address (e.x. Ленинский пр. 161, 13) or location (e.x. 30.23 60.132) for it:\n",
      "\n",
      "Got address: , detect location (68.015588, 168.948015)\n",
      "Please, enter datetime (e.x. 2021-10-25 09:31:32) for it:\n",
      "\n"
     ]
    },
    {
     "name": "stderr",
     "output_type": "stream",
     "text": [
      "ERROR:root:Can not get datetime from string \n",
      "--- Logging error ---\n",
      "Traceback (most recent call last):\n",
      "  File \"/Users/tiginamaria1999/PycharmProjects/itmo_ct/database/database_client_sqlite.py\", line 145, in _add_images_info_to_database\n",
      "    self._add_exif_info_for_image(image_id)\n",
      "  File \"/Users/tiginamaria1999/PycharmProjects/itmo_ct/database/database_client_sqlite.py\", line 101, in _add_exif_info_for_image\n",
      "    raise Exception(f\"Failed to get or read exif info for image: {image_id}\")\n",
      "Exception: Failed to get or read exif info for image: 45\n",
      "\n",
      "During handling of the above exception, another exception occurred:\n",
      "\n",
      "Traceback (most recent call last):\n",
      "  File \"/usr/local/Cellar/python@3.9/3.9.6/Frameworks/Python.framework/Versions/3.9/lib/python3.9/logging/__init__.py\", line 1083, in emit\n",
      "    msg = self.format(record)\n",
      "  File \"/usr/local/Cellar/python@3.9/3.9.6/Frameworks/Python.framework/Versions/3.9/lib/python3.9/logging/__init__.py\", line 927, in format\n",
      "    return fmt.format(record)\n",
      "  File \"/usr/local/Cellar/python@3.9/3.9.6/Frameworks/Python.framework/Versions/3.9/lib/python3.9/logging/__init__.py\", line 663, in format\n",
      "    record.message = record.getMessage()\n",
      "  File \"/usr/local/Cellar/python@3.9/3.9.6/Frameworks/Python.framework/Versions/3.9/lib/python3.9/logging/__init__.py\", line 367, in getMessage\n",
      "    msg = msg % self.args\n",
      "TypeError: not all arguments converted during string formatting\n",
      "Call stack:\n",
      "  File \"/usr/local/Cellar/python@3.9/3.9.6/Frameworks/Python.framework/Versions/3.9/lib/python3.9/runpy.py\", line 197, in _run_module_as_main\n",
      "    return _run_code(code, main_globals, None,\n",
      "  File \"/usr/local/Cellar/python@3.9/3.9.6/Frameworks/Python.framework/Versions/3.9/lib/python3.9/runpy.py\", line 87, in _run_code\n",
      "    exec(code, run_globals)\n",
      "  File \"/usr/local/lib/python3.9/site-packages/ipykernel_launcher.py\", line 16, in <module>\n",
      "    app.launch_new_instance()\n",
      "  File \"/usr/local/lib/python3.9/site-packages/traitlets/config/application.py\", line 846, in launch_instance\n",
      "    app.start()\n",
      "  File \"/usr/local/lib/python3.9/site-packages/ipykernel/kernelapp.py\", line 677, in start\n",
      "    self.io_loop.start()\n",
      "  File \"/usr/local/lib/python3.9/site-packages/tornado/platform/asyncio.py\", line 199, in start\n",
      "    self.asyncio_loop.run_forever()\n",
      "  File \"/usr/local/Cellar/python@3.9/3.9.6/Frameworks/Python.framework/Versions/3.9/lib/python3.9/asyncio/base_events.py\", line 596, in run_forever\n",
      "    self._run_once()\n",
      "  File \"/usr/local/Cellar/python@3.9/3.9.6/Frameworks/Python.framework/Versions/3.9/lib/python3.9/asyncio/base_events.py\", line 1890, in _run_once\n",
      "    handle._run()\n",
      "  File \"/usr/local/Cellar/python@3.9/3.9.6/Frameworks/Python.framework/Versions/3.9/lib/python3.9/asyncio/events.py\", line 80, in _run\n",
      "    self._context.run(self._callback, *self._args)\n",
      "  File \"/usr/local/lib/python3.9/site-packages/ipykernel/kernelbase.py\", line 457, in dispatch_queue\n",
      "    await self.process_one()\n",
      "  File \"/usr/local/lib/python3.9/site-packages/ipykernel/kernelbase.py\", line 446, in process_one\n",
      "    await dispatch(*args)\n",
      "  File \"/usr/local/lib/python3.9/site-packages/ipykernel/kernelbase.py\", line 353, in dispatch_shell\n",
      "    await result\n",
      "  File \"/usr/local/lib/python3.9/site-packages/ipykernel/kernelbase.py\", line 648, in execute_request\n",
      "    reply_content = await reply_content\n",
      "  File \"/usr/local/lib/python3.9/site-packages/ipykernel/ipkernel.py\", line 353, in do_execute\n",
      "    res = shell.run_cell(code, store_history=store_history, silent=silent)\n",
      "  File \"/usr/local/lib/python3.9/site-packages/ipykernel/zmqshell.py\", line 533, in run_cell\n",
      "    return super(ZMQInteractiveShell, self).run_cell(*args, **kwargs)\n",
      "  File \"/usr/local/lib/python3.9/site-packages/IPython/core/interactiveshell.py\", line 2901, in run_cell\n",
      "    result = self._run_cell(\n",
      "  File \"/usr/local/lib/python3.9/site-packages/IPython/core/interactiveshell.py\", line 2947, in _run_cell\n",
      "    return runner(coro)\n",
      "  File \"/usr/local/lib/python3.9/site-packages/IPython/core/async_helpers.py\", line 68, in _pseudo_sync_runner\n",
      "    coro.send(None)\n",
      "  File \"/usr/local/lib/python3.9/site-packages/IPython/core/interactiveshell.py\", line 3172, in run_cell_async\n",
      "    has_raised = await self.run_ast_nodes(code_ast.body, cell_name,\n",
      "  File \"/usr/local/lib/python3.9/site-packages/IPython/core/interactiveshell.py\", line 3364, in run_ast_nodes\n",
      "    if (await self.run_code(code, result,  async_=asy)):\n",
      "  File \"/usr/local/lib/python3.9/site-packages/IPython/core/interactiveshell.py\", line 3444, in run_code\n",
      "    exec(code_obj, self.user_global_ns, self.user_ns)\n",
      "  File \"/var/folders/4s/hl9y6lqs3h1c9qxxnbjmtvsr0000gn/T/ipykernel_32875/718171376.py\", line 8, in <module>\n",
      "    db_client.add_images(selected_photos)\n",
      "  File \"/Users/tiginamaria1999/PycharmProjects/itmo_ct/database/database_client_sqlite.py\", line 166, in add_images\n",
      "    processed_image_ids = self._add_images_info_to_database(added_image_ids)\n",
      "  File \"/Users/tiginamaria1999/PycharmProjects/itmo_ct/database/database_client_sqlite.py\", line 150, in _add_images_info_to_database\n",
      "    logging.error(f'Skipping image {image_id} due to error: {e}')\n",
      "Message: 'Skipping image 45 due to error:'\n",
      "Arguments: (Exception('Failed to get or read exif info for image: 45'),)\n",
      "WARNING:root:DateTime and GPSInfo not provided in image exif data.\n"
     ]
    },
    {
     "name": "stdout",
     "output_type": "stream",
     "text": [
      "Service can not detect where IMG_4378.JPG was made?\n",
      "Please, enter address (e.x. Ленинский пр. 161, 13) or location (e.x. 30.23 60.132) for it:\n",
      "\n",
      "Got address: , detect location (68.015588, 168.948015)\n",
      "Please, enter datetime (e.x. 2021-10-25 09:31:32) for it:\n",
      "\n"
     ]
    },
    {
     "name": "stderr",
     "output_type": "stream",
     "text": [
      "ERROR:root:Can not get datetime from string \n",
      "--- Logging error ---\n",
      "Traceback (most recent call last):\n",
      "  File \"/Users/tiginamaria1999/PycharmProjects/itmo_ct/database/database_client_sqlite.py\", line 145, in _add_images_info_to_database\n",
      "    self._add_exif_info_for_image(image_id)\n",
      "  File \"/Users/tiginamaria1999/PycharmProjects/itmo_ct/database/database_client_sqlite.py\", line 101, in _add_exif_info_for_image\n",
      "    raise Exception(f\"Failed to get or read exif info for image: {image_id}\")\n",
      "Exception: Failed to get or read exif info for image: 46\n",
      "\n",
      "During handling of the above exception, another exception occurred:\n",
      "\n",
      "Traceback (most recent call last):\n",
      "  File \"/usr/local/Cellar/python@3.9/3.9.6/Frameworks/Python.framework/Versions/3.9/lib/python3.9/logging/__init__.py\", line 1083, in emit\n",
      "    msg = self.format(record)\n",
      "  File \"/usr/local/Cellar/python@3.9/3.9.6/Frameworks/Python.framework/Versions/3.9/lib/python3.9/logging/__init__.py\", line 927, in format\n",
      "    return fmt.format(record)\n",
      "  File \"/usr/local/Cellar/python@3.9/3.9.6/Frameworks/Python.framework/Versions/3.9/lib/python3.9/logging/__init__.py\", line 663, in format\n",
      "    record.message = record.getMessage()\n",
      "  File \"/usr/local/Cellar/python@3.9/3.9.6/Frameworks/Python.framework/Versions/3.9/lib/python3.9/logging/__init__.py\", line 367, in getMessage\n",
      "    msg = msg % self.args\n",
      "TypeError: not all arguments converted during string formatting\n",
      "Call stack:\n",
      "  File \"/usr/local/Cellar/python@3.9/3.9.6/Frameworks/Python.framework/Versions/3.9/lib/python3.9/runpy.py\", line 197, in _run_module_as_main\n",
      "    return _run_code(code, main_globals, None,\n",
      "  File \"/usr/local/Cellar/python@3.9/3.9.6/Frameworks/Python.framework/Versions/3.9/lib/python3.9/runpy.py\", line 87, in _run_code\n",
      "    exec(code, run_globals)\n",
      "  File \"/usr/local/lib/python3.9/site-packages/ipykernel_launcher.py\", line 16, in <module>\n",
      "    app.launch_new_instance()\n",
      "  File \"/usr/local/lib/python3.9/site-packages/traitlets/config/application.py\", line 846, in launch_instance\n",
      "    app.start()\n",
      "  File \"/usr/local/lib/python3.9/site-packages/ipykernel/kernelapp.py\", line 677, in start\n",
      "    self.io_loop.start()\n",
      "  File \"/usr/local/lib/python3.9/site-packages/tornado/platform/asyncio.py\", line 199, in start\n",
      "    self.asyncio_loop.run_forever()\n",
      "  File \"/usr/local/Cellar/python@3.9/3.9.6/Frameworks/Python.framework/Versions/3.9/lib/python3.9/asyncio/base_events.py\", line 596, in run_forever\n",
      "    self._run_once()\n",
      "  File \"/usr/local/Cellar/python@3.9/3.9.6/Frameworks/Python.framework/Versions/3.9/lib/python3.9/asyncio/base_events.py\", line 1890, in _run_once\n",
      "    handle._run()\n",
      "  File \"/usr/local/Cellar/python@3.9/3.9.6/Frameworks/Python.framework/Versions/3.9/lib/python3.9/asyncio/events.py\", line 80, in _run\n",
      "    self._context.run(self._callback, *self._args)\n",
      "  File \"/usr/local/lib/python3.9/site-packages/ipykernel/kernelbase.py\", line 457, in dispatch_queue\n",
      "    await self.process_one()\n",
      "  File \"/usr/local/lib/python3.9/site-packages/ipykernel/kernelbase.py\", line 446, in process_one\n",
      "    await dispatch(*args)\n",
      "  File \"/usr/local/lib/python3.9/site-packages/ipykernel/kernelbase.py\", line 353, in dispatch_shell\n",
      "    await result\n",
      "  File \"/usr/local/lib/python3.9/site-packages/ipykernel/kernelbase.py\", line 648, in execute_request\n",
      "    reply_content = await reply_content\n",
      "  File \"/usr/local/lib/python3.9/site-packages/ipykernel/ipkernel.py\", line 353, in do_execute\n",
      "    res = shell.run_cell(code, store_history=store_history, silent=silent)\n",
      "  File \"/usr/local/lib/python3.9/site-packages/ipykernel/zmqshell.py\", line 533, in run_cell\n",
      "    return super(ZMQInteractiveShell, self).run_cell(*args, **kwargs)\n",
      "  File \"/usr/local/lib/python3.9/site-packages/IPython/core/interactiveshell.py\", line 2901, in run_cell\n",
      "    result = self._run_cell(\n",
      "  File \"/usr/local/lib/python3.9/site-packages/IPython/core/interactiveshell.py\", line 2947, in _run_cell\n",
      "    return runner(coro)\n",
      "  File \"/usr/local/lib/python3.9/site-packages/IPython/core/async_helpers.py\", line 68, in _pseudo_sync_runner\n",
      "    coro.send(None)\n",
      "  File \"/usr/local/lib/python3.9/site-packages/IPython/core/interactiveshell.py\", line 3172, in run_cell_async\n",
      "    has_raised = await self.run_ast_nodes(code_ast.body, cell_name,\n",
      "  File \"/usr/local/lib/python3.9/site-packages/IPython/core/interactiveshell.py\", line 3364, in run_ast_nodes\n",
      "    if (await self.run_code(code, result,  async_=asy)):\n",
      "  File \"/usr/local/lib/python3.9/site-packages/IPython/core/interactiveshell.py\", line 3444, in run_code\n",
      "    exec(code_obj, self.user_global_ns, self.user_ns)\n",
      "  File \"/var/folders/4s/hl9y6lqs3h1c9qxxnbjmtvsr0000gn/T/ipykernel_32875/718171376.py\", line 8, in <module>\n",
      "    db_client.add_images(selected_photos)\n",
      "  File \"/Users/tiginamaria1999/PycharmProjects/itmo_ct/database/database_client_sqlite.py\", line 166, in add_images\n",
      "    processed_image_ids = self._add_images_info_to_database(added_image_ids)\n",
      "  File \"/Users/tiginamaria1999/PycharmProjects/itmo_ct/database/database_client_sqlite.py\", line 150, in _add_images_info_to_database\n",
      "    logging.error(f'Skipping image {image_id} due to error: {e}')\n",
      "Message: 'Skipping image 46 due to error:'\n",
      "Arguments: (Exception('Failed to get or read exif info for image: 46'),)\n"
     ]
    },
    {
     "name": "stdout",
     "output_type": "stream",
     "text": [
      "19/25 have been successfully processed\n"
     ]
    }
   ],
   "source": [
    "# Importing required modules\n",
    "from database.database_client_sqlite import ImageDatabaseSQLiteClient\n",
    "\n",
    "# Creating new database client instance\n",
    "db_client = ImageDatabaseSQLiteClient()\n",
    "\n",
    "# Add all selected images to database\n",
    "db_client.add_images(selected_photos)\n",
    "        "
   ]
  },
  {
   "cell_type": "code",
   "execution_count": null,
   "id": "2ad40dd1",
   "metadata": {},
   "outputs": [],
   "source": []
  }
 ],
 "metadata": {
  "kernelspec": {
   "display_name": "Python 3 (ipykernel)",
   "language": "python",
   "name": "python3"
  },
  "language_info": {
   "codemirror_mode": {
    "name": "ipython",
    "version": 3
   },
   "file_extension": ".py",
   "mimetype": "text/x-python",
   "name": "python",
   "nbconvert_exporter": "python",
   "pygments_lexer": "ipython3",
   "version": "3.9.6"
  }
 },
 "nbformat": 4,
 "nbformat_minor": 5
}
